[2022-09-02T13:34:12.744+0000] {taskinstance.py:1171} INFO - Dependencies all met for <TaskInstance: test_dag_v1.create_postgres_table scheduled__2022-09-01T00:00:00+00:00 [queued]>
[2022-09-02T13:34:12.752+0000] {taskinstance.py:1171} INFO - Dependencies all met for <TaskInstance: test_dag_v1.create_postgres_table scheduled__2022-09-01T00:00:00+00:00 [queued]>
[2022-09-02T13:34:12.753+0000] {taskinstance.py:1368} INFO - 
--------------------------------------------------------------------------------
[2022-09-02T13:34:12.754+0000] {taskinstance.py:1369} INFO - Starting attempt 6 of 11
[2022-09-02T13:34:12.755+0000] {taskinstance.py:1370} INFO - 
--------------------------------------------------------------------------------
[2022-09-02T13:34:12.765+0000] {taskinstance.py:1389} INFO - Executing <Task(PostgresOperator): create_postgres_table> on 2022-09-01 00:00:00+00:00
[2022-09-02T13:34:12.770+0000] {standard_task_runner.py:52} INFO - Started process 4719 to run task
[2022-09-02T13:34:12.773+0000] {standard_task_runner.py:79} INFO - Running: ['***', 'tasks', 'run', 'test_dag_v1', 'create_postgres_table', 'scheduled__2022-09-01T00:00:00+00:00', '--job-id', '8', '--raw', '--subdir', 'DAGS_FOLDER/test_dag.py', '--cfg-path', '/tmp/tmpiz7u5k9x', '--error-file', '/tmp/tmpbn4_y99c']
[2022-09-02T13:34:12.775+0000] {standard_task_runner.py:80} INFO - Job 8: Subtask create_postgres_table
[2022-09-02T13:34:12.818+0000] {task_command.py:371} INFO - Running <TaskInstance: test_dag_v1.create_postgres_table scheduled__2022-09-01T00:00:00+00:00 [running]> on host 65babab7b35d
[2022-09-02T13:34:12.839+0000] {taskinstance.py:1902} ERROR - Task failed with exception
Traceback (most recent call last):
  File "/home/airflow/.local/lib/python3.7/site-packages/airflow/models/taskinstance.py", line 1463, in _run_raw_task
    self._execute_task_with_callbacks(context, test_mode)
  File "/home/airflow/.local/lib/python3.7/site-packages/airflow/models/taskinstance.py", line 1567, in _execute_task_with_callbacks
    task_orig = self.render_templates(context=context)
  File "/home/airflow/.local/lib/python3.7/site-packages/airflow/models/taskinstance.py", line 2225, in render_templates
    rendered_task = self.task.render_template_fields(context)
  File "/home/airflow/.local/lib/python3.7/site-packages/airflow/models/baseoperator.py", line 1188, in render_template_fields
    self._do_render_template_fields(self, self.template_fields, context, jinja_env, set())
  File "/home/airflow/.local/lib/python3.7/site-packages/airflow/utils/session.py", line 71, in wrapper
    return func(*args, session=session, **kwargs)
  File "/home/airflow/.local/lib/python3.7/site-packages/airflow/models/abstractoperator.py", line 347, in _do_render_template_fields
    seen_oids,
  File "/home/airflow/.local/lib/python3.7/site-packages/airflow/models/abstractoperator.py", line 384, in render_template
    template = jinja_env.get_template(value)
  File "/home/airflow/.local/lib/python3.7/site-packages/jinja2/environment.py", line 1010, in get_template
    return self._load_template(name, globals)
  File "/home/airflow/.local/lib/python3.7/site-packages/jinja2/environment.py", line 969, in _load_template
    template = self.loader.load(self, name, self.make_globals(globals))
  File "/home/airflow/.local/lib/python3.7/site-packages/jinja2/loaders.py", line 126, in load
    source, filename, uptodate = self.get_source(environment, name)
  File "/home/airflow/.local/lib/python3.7/site-packages/jinja2/loaders.py", line 218, in get_source
    raise TemplateNotFound(template)
jinja2.exceptions.TemplateNotFound: include/create_dag_runs.sql
[2022-09-02T13:34:12.847+0000] {taskinstance.py:1412} INFO - Marking task as UP_FOR_RETRY. dag_id=test_dag_v1, task_id=create_postgres_table, execution_date=20220901T000000, start_date=20220902T133412, end_date=20220902T133412
[2022-09-02T13:34:12.941+0000] {standard_task_runner.py:97} ERROR - Failed to execute job 8 for task create_postgres_table (include/create_dag_runs.sql; 4719)
[2022-09-02T13:34:12.988+0000] {local_task_job.py:156} INFO - Task exited with return code 1
[2022-09-02T13:34:13.010+0000] {local_task_job.py:279} INFO - 0 downstream tasks scheduled from follow-on schedule check
