[2022-09-02T13:21:15.875+0000] {taskinstance.py:1171} INFO - Dependencies all met for <TaskInstance: test_dag_v1.create_postgres_table scheduled__2022-09-01T00:00:00+00:00 [queued]>
[2022-09-02T13:21:15.882+0000] {taskinstance.py:1171} INFO - Dependencies all met for <TaskInstance: test_dag_v1.create_postgres_table scheduled__2022-09-01T00:00:00+00:00 [queued]>
[2022-09-02T13:21:15.883+0000] {taskinstance.py:1368} INFO - 
--------------------------------------------------------------------------------
[2022-09-02T13:21:15.884+0000] {taskinstance.py:1369} INFO - Starting attempt 1 of 6
[2022-09-02T13:21:15.885+0000] {taskinstance.py:1370} INFO - 
--------------------------------------------------------------------------------
[2022-09-02T13:21:15.893+0000] {taskinstance.py:1389} INFO - Executing <Task(PostgresOperator): create_postgres_table> on 2022-09-01 00:00:00+00:00
[2022-09-02T13:21:15.897+0000] {standard_task_runner.py:52} INFO - Started process 3922 to run task
[2022-09-02T13:21:15.900+0000] {standard_task_runner.py:79} INFO - Running: ['***', 'tasks', 'run', 'test_dag_v1', 'create_postgres_table', 'scheduled__2022-09-01T00:00:00+00:00', '--job-id', '3', '--raw', '--subdir', 'DAGS_FOLDER/test_dag.py', '--cfg-path', '/tmp/tmp8g635rzh', '--error-file', '/tmp/tmpxxa1hjlp']
[2022-09-02T13:21:15.902+0000] {standard_task_runner.py:80} INFO - Job 3: Subtask create_postgres_table
[2022-09-02T13:21:15.945+0000] {task_command.py:371} INFO - Running <TaskInstance: test_dag_v1.create_postgres_table scheduled__2022-09-01T00:00:00+00:00 [running]> on host 65babab7b35d
[2022-09-02T13:21:15.967+0000] {taskinstance.py:1902} ERROR - Task failed with exception
Traceback (most recent call last):
  File "/home/airflow/.local/lib/python3.7/site-packages/airflow/models/taskinstance.py", line 1463, in _run_raw_task
    self._execute_task_with_callbacks(context, test_mode)
  File "/home/airflow/.local/lib/python3.7/site-packages/airflow/models/taskinstance.py", line 1567, in _execute_task_with_callbacks
    task_orig = self.render_templates(context=context)
  File "/home/airflow/.local/lib/python3.7/site-packages/airflow/models/taskinstance.py", line 2225, in render_templates
    rendered_task = self.task.render_template_fields(context)
  File "/home/airflow/.local/lib/python3.7/site-packages/airflow/models/baseoperator.py", line 1188, in render_template_fields
    self._do_render_template_fields(self, self.template_fields, context, jinja_env, set())
  File "/home/airflow/.local/lib/python3.7/site-packages/airflow/utils/session.py", line 71, in wrapper
    return func(*args, session=session, **kwargs)
  File "/home/airflow/.local/lib/python3.7/site-packages/airflow/models/abstractoperator.py", line 347, in _do_render_template_fields
    seen_oids,
  File "/home/airflow/.local/lib/python3.7/site-packages/airflow/models/abstractoperator.py", line 384, in render_template
    template = jinja_env.get_template(value)
  File "/home/airflow/.local/lib/python3.7/site-packages/jinja2/environment.py", line 1010, in get_template
    return self._load_template(name, globals)
  File "/home/airflow/.local/lib/python3.7/site-packages/jinja2/environment.py", line 969, in _load_template
    template = self.loader.load(self, name, self.make_globals(globals))
  File "/home/airflow/.local/lib/python3.7/site-packages/jinja2/loaders.py", line 126, in load
    source, filename, uptodate = self.get_source(environment, name)
  File "/home/airflow/.local/lib/python3.7/site-packages/jinja2/loaders.py", line 218, in get_source
    raise TemplateNotFound(template)
jinja2.exceptions.TemplateNotFound: create_dag_runs.sql
[2022-09-02T13:21:15.975+0000] {taskinstance.py:1412} INFO - Marking task as UP_FOR_RETRY. dag_id=test_dag_v1, task_id=create_postgres_table, execution_date=20220901T000000, start_date=20220902T132115, end_date=20220902T132115
[2022-09-02T13:21:16.073+0000] {standard_task_runner.py:97} ERROR - Failed to execute job 3 for task create_postgres_table (create_dag_runs.sql; 3922)
[2022-09-02T13:21:16.114+0000] {local_task_job.py:156} INFO - Task exited with return code 1
[2022-09-02T13:21:16.137+0000] {local_task_job.py:279} INFO - 0 downstream tasks scheduled from follow-on schedule check
